Failure # 1 (occurred at 2023-10-03_10-42-46)
[36mray::PPO.train()[39m (pid=4935, ip=172.23.176.38, actor_id=7146716cc3ec593bce7f6f1a01000000, repr=PPO)
  File "/usr/local/lib/python3.10/dist-packages/ray/tune/trainable/trainable.py", line 400, in train
    raise skipped from exception_cause(skipped)
  File "/usr/local/lib/python3.10/dist-packages/ray/tune/trainable/trainable.py", line 397, in train
    result = self.step()
  File "/usr/local/lib/python3.10/dist-packages/ray/rllib/algorithms/algorithm.py", line 853, in step
    results, train_iter_ctx = self._run_one_training_iteration()
  File "/usr/local/lib/python3.10/dist-packages/ray/rllib/algorithms/algorithm.py", line 2832, in _run_one_training_iteration
    results = self.training_step()
  File "/usr/local/lib/python3.10/dist-packages/ray/rllib/algorithms/ppo/ppo.py", line 429, in training_step
    train_batch = synchronous_parallel_sample(
  File "/usr/local/lib/python3.10/dist-packages/ray/rllib/execution/rollout_ops.py", line 85, in synchronous_parallel_sample
    sample_batches = worker_set.foreach_worker(
  File "/usr/local/lib/python3.10/dist-packages/ray/rllib/evaluation/worker_set.py", line 680, in foreach_worker
    handle_remote_call_result_errors(remote_results, self._ignore_worker_failures)
  File "/usr/local/lib/python3.10/dist-packages/ray/rllib/evaluation/worker_set.py", line 76, in handle_remote_call_result_errors
    raise r.get()
ray.exceptions.RayTaskError(ValueError): [36mray::RolloutWorker.apply()[39m (pid=5300, ip=172.23.176.38, actor_id=1812607e655e00b787d4c00801000000, repr=<ray.rllib.evaluation.rollout_worker.RolloutWorker object at 0x7fa9586ec760>)
  File "/usr/local/lib/python3.10/dist-packages/ray/rllib/utils/actor_manager.py", line 185, in apply
    raise e
  File "/usr/local/lib/python3.10/dist-packages/ray/rllib/utils/actor_manager.py", line 176, in apply
    return func(self, *args, **kwargs)
  File "/usr/local/lib/python3.10/dist-packages/ray/rllib/execution/rollout_ops.py", line 86, in <lambda>
    lambda w: w.sample(), local_worker=False, healthy_only=True
  File "/usr/local/lib/python3.10/dist-packages/ray/rllib/evaluation/rollout_worker.py", line 696, in sample
    batches = [self.input_reader.next()]
  File "/usr/local/lib/python3.10/dist-packages/ray/rllib/evaluation/sampler.py", line 92, in next
    batches = [self.get_data()]
  File "/usr/local/lib/python3.10/dist-packages/ray/rllib/evaluation/sampler.py", line 277, in get_data
    item = next(self._env_runner)
  File "/usr/local/lib/python3.10/dist-packages/ray/rllib/evaluation/env_runner_v2.py", line 344, in run
    outputs = self.step()
  File "/usr/local/lib/python3.10/dist-packages/ray/rllib/evaluation/env_runner_v2.py", line 370, in step
    active_envs, to_eval, outputs = self._process_observations(
  File "/usr/local/lib/python3.10/dist-packages/ray/rllib/evaluation/env_runner_v2.py", line 637, in _process_observations
    processed = policy.agent_connectors(acd_list)
  File "/usr/local/lib/python3.10/dist-packages/ray/rllib/connectors/agent/pipeline.py", line 41, in __call__
    ret = c(ret)
  File "/usr/local/lib/python3.10/dist-packages/ray/rllib/connectors/connector.py", line 265, in __call__
    return [self.transform(d) for d in acd_list]
  File "/usr/local/lib/python3.10/dist-packages/ray/rllib/connectors/connector.py", line 265, in <listcomp>
    return [self.transform(d) for d in acd_list]
  File "/usr/local/lib/python3.10/dist-packages/ray/rllib/connectors/agent/obs_preproc.py", line 58, in transform
    d[SampleBatch.NEXT_OBS] = self._preprocessor.transform(
  File "/usr/local/lib/python3.10/dist-packages/ray/rllib/models/preprocessors.py", line 206, in transform
    self.check_shape(observation)
  File "/usr/local/lib/python3.10/dist-packages/ray/rllib/models/preprocessors.py", line 74, in check_shape
    raise ValueError(
ValueError: Observation ([0. 0. 0. 0. 1. 0. 0. 1. 0. 0. 0. 1. 0. 0. 0. 0. 0. 0. 1. 0.] dtype=float32) outside given space (Box(0.0, 5.0, (4,), float32))!
