Failure # 1 (occurred at 2023-10-02_16-06-16)
The actor died because of an error raised in its creation task, [36mray::DQN.__init__()[39m (pid=18614, ip=172.26.22.84, actor_id=8b59378ce1f13073cf1f841f01000000, repr=DQN)
  File "/usr/local/lib/python3.10/dist-packages/ray/rllib/evaluation/worker_set.py", line 227, in _setup
    self.add_workers(
  File "/usr/local/lib/python3.10/dist-packages/ray/rllib/evaluation/worker_set.py", line 593, in add_workers
    raise result.get()
  File "/usr/local/lib/python3.10/dist-packages/ray/rllib/utils/actor_manager.py", line 481, in __fetch_result
    result = ray.get(r)
ray.exceptions.RayActorError: The actor died because of an error raised in its creation task, [36mray::RolloutWorker.__init__()[39m (pid=18892, ip=172.26.22.84, actor_id=85771f5d317415ff87ae241201000000, repr=<ray.rllib.evaluation.rollout_worker.RolloutWorker object at 0x7f8ef1778ee0>)
  File "/usr/local/lib/python3.10/dist-packages/ray/rllib/evaluation/rollout_worker.py", line 525, in __init__
    self._update_policy_map(policy_dict=self.policy_dict)
  File "/usr/local/lib/python3.10/dist-packages/ray/rllib/evaluation/rollout_worker.py", line 1727, in _update_policy_map
    self._build_policy_map(
  File "/usr/local/lib/python3.10/dist-packages/ray/rllib/evaluation/rollout_worker.py", line 1838, in _build_policy_map
    new_policy = create_policy_for_framework(
  File "/usr/local/lib/python3.10/dist-packages/ray/rllib/utils/policy.py", line 142, in create_policy_for_framework
    return policy_class(observation_space, action_space, merged_config)
  File "/usr/local/lib/python3.10/dist-packages/ray/rllib/policy/policy_template.py", line 280, in __init__
    self.model, dist_class = make_model_and_action_dist(
  File "/usr/local/lib/python3.10/dist-packages/ray/rllib/algorithms/dqn/dqn_torch_policy.py", line 183, in build_q_model_and_distribution
    model = ModelCatalog.get_model_v2(
  File "/usr/local/lib/python3.10/dist-packages/ray/rllib/models/catalog.py", line 722, in get_model_v2
    return wrapper(
  File "/usr/local/lib/python3.10/dist-packages/ray/rllib/algorithms/dqn/dqn_torch_model.py", line 76, in __init__
    for i, n in enumerate(q_hiddens):
TypeError: 'int' object is not iterable

During handling of the above exception, another exception occurred:

[36mray::DQN.__init__()[39m (pid=18614, ip=172.26.22.84, actor_id=8b59378ce1f13073cf1f841f01000000, repr=DQN)
  File "/usr/local/lib/python3.10/dist-packages/ray/rllib/utils/deprecation.py", line 106, in patched_init
    return obj_init(*args, **kwargs)
  File "/usr/local/lib/python3.10/dist-packages/ray/rllib/algorithms/algorithm.py", line 517, in __init__
    super().__init__(
  File "/usr/local/lib/python3.10/dist-packages/ray/tune/trainable/trainable.py", line 185, in __init__
    self.setup(copy.deepcopy(self.config))
  File "/usr/local/lib/python3.10/dist-packages/ray/rllib/algorithms/algorithm.py", line 639, in setup
    self.workers = WorkerSet(
  File "/usr/local/lib/python3.10/dist-packages/ray/rllib/evaluation/worker_set.py", line 179, in __init__
    raise e.args[0].args[2]
TypeError: 'int' object is not iterable
